[2024-03-13T11:49:45.606+0000] {taskinstance.py:1979} INFO - Dependencies all met for dep_context=non-requeueable deps ti=<TaskInstance: indeed_scraper.scrape_indeed_data manual__2024-03-13T11:49:40.680253+00:00 [queued]>
[2024-03-13T11:49:45.614+0000] {taskinstance.py:1979} INFO - Dependencies all met for dep_context=requeueable deps ti=<TaskInstance: indeed_scraper.scrape_indeed_data manual__2024-03-13T11:49:40.680253+00:00 [queued]>
[2024-03-13T11:49:45.614+0000] {taskinstance.py:2193} INFO - Starting attempt 1 of 4
[2024-03-13T11:49:45.633+0000] {taskinstance.py:2214} INFO - Executing <Task(_PythonDecoratedOperator): scrape_indeed_data> on 2024-03-13 11:49:40.680253+00:00
[2024-03-13T11:49:45.673+0000] {standard_task_runner.py:60} INFO - Started process 57 to run task
[2024-03-13T11:49:45.690+0000] {standard_task_runner.py:87} INFO - Running: ['***', 'tasks', 'run', 'indeed_scraper', 'scrape_indeed_data', 'manual__2024-03-13T11:49:40.680253+00:00', '--job-id', '53', '--raw', '--subdir', 'DAGS_FOLDER/indeed_scraper.py', '--cfg-path', '/tmp/tmpc62slye4']
[2024-03-13T11:49:45.697+0000] {standard_task_runner.py:88} INFO - Job 53: Subtask scrape_indeed_data
[2024-03-13T11:49:45.774+0000] {task_command.py:423} INFO - Running <TaskInstance: indeed_scraper.scrape_indeed_data manual__2024-03-13T11:49:40.680253+00:00 [running]> on host 69126258c10f
[2024-03-13T11:49:45.906+0000] {taskinstance.py:2510} INFO - Exporting env vars: AIRFLOW_CTX_DAG_OWNER='***' AIRFLOW_CTX_DAG_ID='indeed_scraper' AIRFLOW_CTX_TASK_ID='scrape_indeed_data' AIRFLOW_CTX_EXECUTION_DATE='2024-03-13T11:49:40.680253+00:00' AIRFLOW_CTX_TRY_NUMBER='1' AIRFLOW_CTX_DAG_RUN_ID='manual__2024-03-13T11:49:40.680253+00:00'
[2024-03-13T11:49:45.913+0000] {taskinstance.py:2728} ERROR - Task failed with exception
Traceback (most recent call last):
  File "/home/airflow/.local/lib/python3.9/site-packages/selenium/webdriver/common/driver_finder.py", line 38, in get_path
    path = SeleniumManager().driver_location(options) if path is None else path
  File "/home/airflow/.local/lib/python3.9/site-packages/selenium/webdriver/common/selenium_manager.py", line 89, in driver_location
    args = [str(self.get_binary()), "--browser", browser]
  File "/home/airflow/.local/lib/python3.9/site-packages/selenium/webdriver/common/selenium_manager.py", line 63, in get_binary
    raise WebDriverException(f"Unsupported platform/architecture combination: {sys.platform}/{arch}")
selenium.common.exceptions.WebDriverException: Message: Unsupported platform/architecture combination: linux/aarch64


The above exception was the direct cause of the following exception:

Traceback (most recent call last):
  File "/home/airflow/.local/lib/python3.9/site-packages/airflow/models/taskinstance.py", line 444, in _execute_task
    result = _execute_callable(context=context, **execute_callable_kwargs)
  File "/home/airflow/.local/lib/python3.9/site-packages/airflow/models/taskinstance.py", line 414, in _execute_callable
    return execute_callable(context=context, **execute_callable_kwargs)
  File "/home/airflow/.local/lib/python3.9/site-packages/airflow/decorators/base.py", line 241, in execute
    return_value = super().execute(context)
  File "/home/airflow/.local/lib/python3.9/site-packages/airflow/operators/python.py", line 200, in execute
    return_value = self.execute_callable()
  File "/home/airflow/.local/lib/python3.9/site-packages/airflow/operators/python.py", line 217, in execute_callable
    return self.python_callable(*self.op_args, **self.op_kwargs)
  File "/opt/airflow/dags/indeed_scraper.py", line 77, in scrape_indeed_data
    driver = webdriver.Chrome(options=chrome_options)
  File "/home/airflow/.local/lib/python3.9/site-packages/selenium/webdriver/chrome/webdriver.py", line 45, in __init__
    super().__init__(
  File "/home/airflow/.local/lib/python3.9/site-packages/selenium/webdriver/chromium/webdriver.py", line 49, in __init__
    self.service.path = DriverFinder.get_path(self.service, options)
  File "/home/airflow/.local/lib/python3.9/site-packages/selenium/webdriver/common/driver_finder.py", line 41, in get_path
    raise NoSuchDriverException(msg) from err
selenium.common.exceptions.NoSuchDriverException: Message: Unable to obtain driver for chrome using Selenium Manager.; For documentation on this error, please visit: https://www.selenium.dev/documentation/webdriver/troubleshooting/errors/driver_location

[2024-03-13T11:49:45.939+0000] {taskinstance.py:1149} INFO - Marking task as UP_FOR_RETRY. dag_id=indeed_scraper, task_id=scrape_indeed_data, execution_date=20240313T114940, start_date=20240313T114945, end_date=20240313T114945
[2024-03-13T11:49:45.956+0000] {standard_task_runner.py:107} ERROR - Failed to execute job 53 for task scrape_indeed_data (Message: Unable to obtain driver for chrome using Selenium Manager.; For documentation on this error, please visit: https://www.selenium.dev/documentation/webdriver/troubleshooting/errors/driver_location
; 57)
[2024-03-13T11:49:45.995+0000] {local_task_job_runner.py:234} INFO - Task exited with return code 1
[2024-03-13T11:49:46.012+0000] {taskinstance.py:3309} INFO - 0 downstream tasks scheduled from follow-on schedule check
